<robot name="fetch">
  <link name="base_link">
    <inertial>
      <origin rpy="0 0 0" xyz="-0.0036 0.0 0.0014" />
      <mass value="70.1294" />
      <inertia ixx="1.225" ixy="0.0099" ixz="0.0062" iyy="1.2853" iyz="-0.0034" izz="0.987" />
    </inertial>
    <visual>
      <origin rpy="0 0 0" xyz="0 0 0" />
      <geometry>
        <mesh filename="package://momafetch_description/meshes/base_link.dae" />
      </geometry>
      <material name="">
        <color rgba="0.356 0.361 0.376 1" />
      </material>
    </visual>
    <collision>
      <origin rpy="0 0 0" xyz="0 0 0" />
      <geometry>
        <mesh filename="package://momafetch_description/meshes/base_link_collision.STL" />
      </geometry>
    </collision>
  </link>
   <link name="r_wheel_link">
    <inertial>
      <origin rpy="0 0 0" xyz="0 0 0" />
      <mass value="4.3542" />
      <inertia ixx="0.0045" ixy="0" ixz="0" iyy="0.005" iyz="0" izz="0.0045" />
    </inertial>
    <visual>
      <origin rpy="0 0 0" xyz="0 0 0" />
      <geometry>
        <mesh filename="package://momafetch_description/meshes/r_wheel_link.STL" />
      </geometry>
      <material name="">
        <color rgba="0.086 0.506 0.767 1" />
      </material>
    </visual>
    <collision>
      <origin rpy="1.57079632679 1.57079632679 0" xyz="0 0 0" />
      <geometry>
        <cylinder radius="0.0603" length="0.06" />
      </geometry>
    </collision>
  </link>
  <joint name="r_wheel_joint" type="revolute">
    <origin rpy="-6.123E-17 0 0" xyz="0.0012914 -0.18738 0.055325" />
    <parent link="base_link" />
    <child link="r_wheel_link" />
    <axis xyz="0 1 0" />
    <limit effort="8.85" velocity="17.4" lower="-300" upper="300" />
  </joint>

  <link name="l_wheel_link">
    <inertial>
      <origin rpy="0 0 0" xyz="0 0 0" />
      <mass value="4.3542" />
      <inertia ixx="0.0045" ixy="0" ixz="0" iyy="0.005" iyz="0" izz="0.0045" />
    </inertial>
    <visual>
      <origin rpy="0 0 0" xyz="0 0 0" />
      <geometry>
        <mesh filename="package://momafetch_description/meshes/l_wheel_link.STL" />
      </geometry>
      <material name="">
        <color rgba="0.086 0.506 0.767 1" />
      </material>
    </visual>
    <collision>
      <origin rpy="1.57079632679 1.57079632679 0" xyz="0 0 0" />
      <geometry>
        <cylinder radius="0.0603" length="0.06" />
      </geometry>
    </collision>
  </link>
  <joint name="l_wheel_joint" type="revolute">
    <origin rpy="-6.123E-17 0 0" xyz="0.0012914 0.18738 0.055325" />
    <parent link="base_link" />
    <child link="l_wheel_link" />
    <axis xyz="0 1 0" />
    <limit effort="8.85" velocity="17.4" lower="-300" upper="300" />
  </joint>

  <link name="bl_caster_link">
    <inertial>
      <mass value="0.5"/>
      <origin xyz="0 0 0"/>
      <inertia ixx="0.001" ixy="0.0" ixz="0.0" iyy="0.001" iyz="0.0" izz="0.001"/>
    </inertial>
    <visual>
      <origin rpy="0 0 0" xyz="0 0 0" />
      <geometry>
        <mesh filename="package://momafetch_description/meshes/r_wheel_link.STL" />
      </geometry>
      <material name="">
        <color rgba="0.086 0.506 0.767 1" />
      </material>
    </visual>
    <collision>
      <origin rpy="1.57079632679 1.57079632679 0" xyz="0 0 0" />
      <geometry>
        <cylinder radius="0.0603" length="0.06" />
      </geometry>
    </collision>
  </link>
  <joint name="bl_caster_joint" type="fixed">
    <parent link="base_link" />
    <child link="bl_caster_link" />
    <origin rpy="0 0 0" xyz="-0.18 -0.12 0.055325" />
    <axis xyz="0 1 0" />
  </joint>

  <link name="br_caster_link">
    <inertial>
      <mass value="0.5"/>
      <origin xyz="0 0 0"/>
      <inertia ixx="0.001" ixy="0.0" ixz="0.0" iyy="0.001" iyz="0.0" izz="0.001"/>
    </inertial>
    <visual>
      <origin rpy="0 0 0" xyz="0 0 0" />
      <geometry>
        <mesh filename="package://momafetch_description/meshes/r_wheel_link.STL" />
      </geometry>
      <material name="">
        <color rgba="0.086 0.506 0.767 1" />
      </material>
    </visual>
    <collision>
      <origin rpy="1.57079632679 1.57079632679 0" xyz="0 0 0" />
      <geometry>
        <cylinder radius="0.0603" length="0.06" />
      </geometry>
    </collision>
  </link>
  <joint name="br_caster_joint" type="fixed">
    <parent link="base_link" />
    <child link="br_caster_link" />
    <origin rpy="0 0 0" xyz="-0.18 0.12 0.055325" />
    <axis xyz="0 1 0" />
  </joint>

  <link name="fl_caster_link">
    <inertial>
      <mass value="0.5"/>
      <origin xyz="0 0 0"/>
      <inertia ixx="0.001" ixy="0.0" ixz="0.0" iyy="0.001" iyz="0.0" izz="0.001"/>
    </inertial>
    <visual>
      <origin rpy="0 0 0" xyz="0 0 0" />
      <geometry>
        <mesh filename="package://momafetch_description/meshes/r_wheel_link.STL" />
      </geometry>
      <material name="">
        <color rgba="0.086 0.506 0.767 1" />
      </material>
    </visual>
    <collision>
      <geometry>
        <sphere radius="0.0603"/> 
      </geometry>
    </collision>
  </link>
  <joint name="fl_caster_joint" type="fixed">
    <parent link="base_link" />
    <child link="fl_caster_link" />
    <origin rpy="0 0 0" xyz="0.18 -0.12 0.055325" />
    <axis xyz="0 1 0" />
  </joint>

  <link name="fr_caster_link">
    <inertial>
      <mass value="0.5"/>
      <origin xyz="0 0 0"/>
      <inertia ixx="0.001" ixy="0.0" ixz="0.0" iyy="0.001" iyz="0.0" izz="0.001"/>
    </inertial>
    <visual>
      <origin rpy="0 0 0" xyz="0 0 0" />
      <geometry>
        <mesh filename="package://momafetch_description/meshes/r_wheel_link.STL" />
      </geometry>
      <material name="">
        <color rgba="0.086 0.506 0.767 1" />
      </material>
    </visual>
    <collision>
      <geometry>
        <sphere radius="0.0603"/> 
      </geometry>
    </collision>
  </link>
  <joint name="fr_caster_joint" type="fixed">
    <parent link="base_link" />
    <child link="fr_caster_link" />
    <origin rpy="0 0 0" xyz="0.18 0.12 0.055325" />
    <axis xyz="0 1 0" />
  </joint>


  <link name="r_wheel_bottom_link" />
  <joint name="r_wheel_bottom_joint" type="fixed">
    <parent link="r_wheel_link" />
    <child link="r_wheel_bottom_link" />
    <origin rpy="0 0 0" xyz="0 0 -0.0603" />
  </joint>  
  <link name="l_wheel_bottom_link" />
  <joint name="l_wheel_bottom_joint" type="fixed">
    <parent link="l_wheel_link" />
    <child link="l_wheel_bottom_link" />
    <origin rpy="0 0 0" xyz="0 0 -0.0603" />
  </joint>

  <link name="caster_link"/>
  <joint name="caster_joint" type="fixed">
    <parent link="base_link" />
    <child link="caster_link" />
    <origin rpy="0 0 0" xyz="0.18 0 0.055325" />
  </joint>   
  <link name="caster_bottom_link" />
  <joint name="caster_bottom_joint" type="fixed">
    <parent link="caster_link" />
    <child link="caster_bottom_link" />
    <origin rpy="0 0 0" xyz="0 0 -0.0603" />
  </joint>

</robot>
